Workbook

Sheet README
A1: FPGA / AI Hardware Product Research Workbook (Template)
A3: How to use:
A5: 1) Go to 'Inputs_Assumptions' and update USD→INR FX, default duty/GST and Amazon fee assumptions.
A6: 2) Go to 'Products_Master' and fill the site prices (Amazon India, India e-commerce, Alibaba/LCSC/Mouser/DigiKey).
A7: 3) For imported items, enter 'Chosen_Import_Price_USD' and select the source you plan to use; the sheet computes landed cost and recommended selling price.
A8: 4) Review 'Inventory_Plans' tabs (5L/10L/20L) — adjust quantities and ensure totals fit your budget.
A9: 5) Use 'FPGA_Board_BOM' to estimate your own branded Artix-7 board manufacturing cost.
A12: Last generated: | B12: 2025-12-20

Sheet Inputs_Assumptions
A1: Assumptions (edit blue cells)
A3: Parameter | B3: Value | C3: Notes
A4: USD→INR FX rate | B4: 83 | C4: Update daily/weekly.
A5: Default Import Duty % | B5: 0.1 | C5: Edit per product/HSN.
A6: Default GST % | B6: 0.18 | C6: Most electronics 18% in India (verify).
A7: Default Ship/Handling per unit (INR) | B7: 150 | C7: Avg shipping+packing; adjust.
A8: Amazon fees % (referral+closing+FBA avg) | B8: 0.18 | C8: Approx; depends category & weight.
A9: Target Gross Margin % (default) | B9: 0.35 | C9: Used for recommended sell price.
A10: IndiaMart lead cost per month (INR) | B10: 40000 | C10: Optional paid subscription.

Sheet Products_Master
A1: SKU | B1: Category | C1: Product_Type | D1: Product_Name | E1: Brand/Manufacturer | F1: Model/Part_Number | G1: Variant | H1: Key_Specs | I1: Use_Case | J1: Target_Customers | K1: Sourcing_Mode | L1: Primary_Supplier_Planned | M1: Planned_Buy_Price_INR | N1: Planned_Sell_Price_INR | O1: Planned_Gross_Margin_% | P1: AmazonIN_Price_INR | Q1: AmazonIN_URL | R1: IndiaEcom_Price_INR | S1: IndiaEcom_URL | T1: Alibaba_Price_USD | U1: Alibaba_URL | V1: LCSC_Price_USD | W1: LCSC_URL | X1: Mouser_Price_USD | Y1: Mouser_URL | Z1: DigiKey_Price_USD | AA1: DigiKey_URL | AB1: MOQ | AC1: Lead_Time_Days | AD1: Ship/Handling_INR | AE1: Import_Duty_% | AF1: GST_% | AG1: FX_USD_INR | AH1: Chosen_Import_Price_USD | AI1: Chosen_Source | AJ1: Landed_Cost_INR | AK1: Target_Gross_Margin_% | AL1: Recommended_Sell_Price_INR | AM1: Amazon_Fees_% | AN1: Net_Margin_Amazon_% | AO1: Priority | AP1: Qty_5L | AQ1: Qty_10L | AR1: Qty_20L | AS1: Expected_Monthly_Units | AT1: Notes | AU1: Last_Checked_Date | AV1: Source_Notes | AX1: AmazonIN_Price_Checked_Date | AY1: AmazonIN_Seller_Name | AZ1: AmazonIN_Seller_URL | BA1: AmazonIN_Seller_Address | BB1: AmazonIN_Seller_Contact | BC1: IndiaEcom_Price_Checked_Date | BD1: IndiaEcom_Vendor_Name | BE1: IndiaEcom_Vendor_URL | BF1: IndiaEcom_Vendor_Address | BG1: IndiaEcom_Vendor_Contact | BH1: Alibaba_Price_Checked_Date | BI1: Alibaba_Supplier_Name | BJ1: Alibaba_Supplier_URL | BK1: Alibaba_Supplier_Address | BL1: Alibaba_Supplier_Contact | BM1: Best_Price_INR | BN1: Best_Price_Source | BO1: Best_Price_URL | BP1: Best_Vendor_Name | BQ1: Best_Vendor_URL | BR1: Best_Vendor_Address | BS1: Best_Vendor_Contact | BT1: Best_Price_Checked_Date | BU1: Price_Notes | BV1: Price_Workability_Notes | BW1: Best_Channels | BX1: Bundle_Idea_To_Raise_ASP | BY1: Amazon_Listing_Copy | BZ1: Listing_Keywords | CA1: Simple_Launch_Plan | CB1: Supplier_Verification_Status | CC1: Supplier_Type_(Authorized/Reseller/OEM) | CD1: Seller_Supplier_Profile_URL | CE1: Verified_Badges | CF1: Alibaba_SellerCentral_Profile | CG1: Evidence_File_Link_(Screenshot/PDF) | CH1: Payment_Method_Safe_(Y/N) | CI1: Sample_Tested_(Y/N) | CJ1: DOA_Terms_(Days) | CK1: Return_Terms | CL1: Incoterms | CM1: Warranty | CN1: Replacement_Timeline | CO1: Approved_Supplier_(Y/N) | CP1: Best_Price_Vendor_(Auto) | CQ1: Best_Price_Site_URL | CR1: Next_Recheck_Date | CS1: Bottom_Line | CT1: Priority_Label | CU1: Priority_Score | CV1: Priority_Score_Breakdown
A2: FPGA-A7-35T | B2: FPGA Board | C2: Board | D2: Artix-7 FPGA Dev Board | E2: AMD/Xilinx | F2: XC7A35T | G2: A35T dev board | H2: Artix-7, ~33k LUT, DDR3, USB-JTAG | I2: FPGA prototyping, DSP, AI accel | J2: Students, Startups | K2: Both | L2: Rynex/Import | M2: 6500 | N2: 8500 | O2: =IF(AND(M2<>"",N2<>""),(N2-M2)/N2,"") -> 0.23529412 | P2: 3371 | Q2: https://www.amazon.in/Arty-A7-Artix-7-Development-Hobbyists/dp/B07D1DVRG6 | S2: =HYPERLINK("https://robu.in/?s="&SUBSTITUTE($D2," ","+")&"&post_type=product","Robu search") -> Robu search | T2: 282.8 | U2: https://www.alibaba.com/showroom/xilinx-fpga-kit.html | W2: =HYPERLINK("https://www.lcsc.com/search?q="&SUBSTITUTE($D2," ","+"),"LCSC search") -> LCSC search | Y2: =HYPERLINK("https://www.mouser.in/c/?q="&SUBSTITUTE($D2," ","+"),"Mouser search") -> Mouser search | AA2: =HYPERLINK("https://www.digikey.in/en/products/filter?keywords="&SUBSTITUTE($D2," ","+"),"DigiKey search") -> DigiKey search | AC2: =Inputs_Assumptions!$B$7 -> 150 | AD2: =Inputs_Assumptions!$B$7 -> 150 | AE2: =Inputs_Assumptions!$B$5 -> 0.1 | AF2: =Inputs_Assumptions!$B$6 -> 0.18 | AG2: =Inputs_Assumptions!$B$4 -> 83 | AJ2: =IF(AH2<>"",(AH2*AG2+AD2)*(1+AE2)*(1+AF2),(M2+AD2)*(1+AF2)) -> 7847 | AK2: =Inputs_Assumptions!$B$9 -> 0.35 | AL2: =IF(AJ2<>"",AJ2/(1-AK2),"") -> 12072.308 | AM2: =Inputs_Assumptions!$B$8 -> 0.18 | AN2: =IF(AND(P2<>"",AJ2<>"",AM2<>""),(P2-AJ2-P2*AM2)/P2,"") -> -1.5077959 | AO2: A | AP2: 4 | AQ2: 8 | AR2: 16 | AS2: 2 | AW2: 2025-12-20 | AX2: 2025-12-21 | BH2: 2025-12-21 | BV2: Risky at planned sell (needs bundle or cheaper sourcing). Gross≈15%. Est Amazon net≈-3% after ~18% fees. | BW2: Direct (B2B) + IndiaMART RFQs; avoid Amazon unless bundled/priced higher; also local resellers. | BX2: Bundle: correct power adapter + USB cable + JTAG cable option + PMOD starter pack + demo bitstream + quick‑start + onboarding call. | BY2: Title: Artix-7 FPGA Dev Board | Verified/QA Tested | Quick‑Start + Support | GST Invoice Bullets: - Key specs: Artix-7, ~33k LUT, DDR3, USB-JTAG - Use case: FPGA prototyping, DSP, AI accel - Pre‑tested unit with packaging QC sticker + photo proof before dispatch. - Support: setup guide (QR) + WhatsApp troubleshooting; replacement DOA policy. - Ideal for startups/labs/training centers; bulk pricing available. | BZ2: fpga development board, zynq board, artix board, cyclone board, vivado board, quartus board, fpga starter kit, pmod | CA2: Day1–2 sample+QC | Day3 assets+pack insert QR | Day4 IndiaMART+WhatsApp catalog | Week1 Amazon (kit) | Week1–2 LinkedIn/B2B outreach | Week2 small ads + optimize | Bi‑weekly price recheck | CB2: Pending (missing seller profile) | CC2: Reseller (needs confirmation) | CE2: Unknown | CH2: N | CI2: N | CJ2: 7 | CK2: 7 days DOA replacement; unopened returns as per channel policy. | CL2: Domestic shipment (GST invoice preferred) | CM2: 3 months (board functional; no over-voltage/ESD damage). | CN2: 7–14 days (confirm with supplier) | CO2: N | CR2: 2026-01-06 | CS2: Risky at planned sell (needs bundle or cheaper sourcing). Gross≈15%. Est Amazon net≈-3% after ~18% fees. | Channels: Direct (B2B) + IndiaMART RFQs; avoid Amazon unless bundled/priced higher; also local resellers. | Bundle: Bundle: correct power adapter + USB cable + JTAG cable option + PMOD starter pack + demo bitstream + quick‑start + onboarding call. | CT2: High | CU2: 30.2 | CV2: Demand 4.0/40 (units=2.0); Margin 0.0/30 (GM%=-2614260161.3); Channel 0.0/10 (AmazonNet%=NA); Sourcing 6.2/10 (mode=Both); Lead 10.0/10 (days=7.0); Fit 10.0/10; Penalty 0.0/10.
A3: FPGA-A7-100T | B3: FPGA Board | C3: Board | D3: Artix-7 FPGA Dev Board | E3: AMD/Xilinx | F3: XC7A100T | G3: A100T dev board | H3: Artix-7, ~101k LUT, DDR3, USB-JTAG | I3: Higher logic prototypes | J3: Startups, Labs | K3: Import | L3: Import | M3: 10500 | N3: 14500 | O3: =IF(AND(M3<>"",N3<>""),(N3-M3)/N3,"") -> 0.27586207 | P3: 66118 | Q3: https://www.amazon.in/Digilent-Arty-A7-100T-Development/dp/B07V2ZC7R2 | S3: =HYPERLINK("https://robu.in/?s="&SUBSTITUTE($D3," ","+")&"&post_type=product","Robu search") -> Robu search | U3: https://www.alibaba.com/trade/search?SearchText=Artix-7+FPGA+Dev+Board+XC7A100T | W3: =HYPERLINK("https://www.lcsc.com/search?q="&SUBSTITUTE($D3," ","+"),"LCSC search") -> LCSC search | Y3: =HYPERLINK("https://www.mouser.in/c/?q="&SUBSTITUTE($D3," ","+"),"Mouser search") -> Mouser search | AA3: =HYPERLINK("https://www.digikey.in/en/products/filter?keywords="&SUBSTITUTE($D3," ","+"),"DigiKey search") -> DigiKey search | AC3: =Inputs_Assumptions!$B$7 -> 150 | AD3: =Inputs_Assumptions!$B$7 -> 150 | AE3: =Inputs_Assumptions!$B$5 -> 0.1 | AF3: =Inputs_Assumptions!$B$6 -> 0.18 | AG3: =Inputs_Assumptions!$B$4 -> 83 | AJ3: =IF(AH3<>"",(AH3*AG3+AD3)*(1+AE3)*(1+AF3),(M3+AD3)*(1+AF3)) -> 12567 | AK3: =Inputs_Assumptions!$B$9 -> 0.35 | AL3: =IF(AJ3<>"",AJ3/(1-AK3),"") -> 19333.846 | AM3: =Inputs_Assumptions!$B$8 -> 0.18 | AN3: =IF(AND(P3<>"",AJ3<>"",AM3<>""),(P3-AJ3-P3*AM3)/P3,"") -> 0.62993073 | AO3: B | AW3: 2025-12-20 | AX3: 2025-12-21 | BH3: 2025-12-21 | BV3: Works for Direct/B2B; marketplaces need bundle/price-up. Gross≈19%. Est Amazon net≈1% after ~18% fees. | BW3: Direct (B2B) + IndiaMART; Amazon only if bundled/priced higher. | BX3: Bundle: correct power adapter + USB cable + JTAG cable option + PMOD starter pack + demo bitstream + quick‑start + onboarding call. | BY3: Title: Artix-7 FPGA Dev Board | Verified/QA Tested | Quick‑Start + Support | GST Invoice Bullets: - Key specs: Artix-7, ~101k LUT, DDR3, USB-JTAG - Use case: Higher logic prototypes - Pre‑tested unit with packaging QC sticker + photo proof before dispatch. - Support: setup guide (QR) + WhatsApp troubleshooting; replacement DOA policy. - Ideal for startups/labs/training centers; bulk pricing available. | BZ3: fpga development board, zynq board, artix board, cyclone board, vivado board, quartus board, fpga starter kit, pmod | CA3: Day1–2 sample+QC | Day3 assets+pack insert QR | Day4 IndiaMART+WhatsApp catalog | Week1 Amazon (kit) | Week1–2 LinkedIn/B2B outreach | Week2 small ads + optimize | Bi‑weekly price recheck | CB3: Pending (missing seller profile) | CC3: Reseller (needs confirmation) | CE3: Unknown | CH3: N | CI3: N | CJ3: 7 | CK3: 7 days DOA replacement; unopened returns as per channel policy. | CL3: Domestic shipment (GST invoice preferred) | CM3: 3 months (board functional; no over-voltage/ESD damage). | CN3: 7–14 days (confirm with supplier) | CO3: N | CR3: 2026-01-06 | CS3: Works for Direct/B2B; marketplaces need bundle/price-up. Gross≈19%. Est Amazon net≈1% after ~18% fees. | Channels: Direct (B2B) + IndiaMART; Amazon only if bundled/priced higher. | Bundle: Bundle: correct power adapter + USB cable + JTAG cable option + PMOD starter pack + demo bitstream + quick‑start + onboarding call. | CT3: Medium | CU3: 25 | CV3: Demand 0.0/40 (units=0.0); Margin 0.0/30 (GM%=-2298711164.2); Channel 5.0/10 (AmazonNet%=NA); Sourcing 0.0/10 (mode=Import); Lead 10.0/10 (days=7.0); Fit 10.0/10; Penalty 0.0/10.
A4: FPGA-ZYNQ-7020 | B4: FPGA Board | C4: Board | D4: Zynq-7000 Dev Board | E4: AMD/Xilinx | F4: XC7Z020 | G4: Z-7020 board | H4: Dual ARM A9 + FPGA fabric, DDR3 | I4: Embedded + HW accel | J4: Startups, Labs | K4: Both | L4: Rynex/Import | M4: 12500 | N4: 15500 | O4: =IF(AND(M4<>"",N4<>""),(N4-M4)/N4,"") -> 0.19354839 | P4: 50750.1 | Q4: https://www.amazon.in/Digilent-Zybo-Z7-Zynq-7000-Development/dp/B0797G4485 | S4: =HYPERLINK("https://robu.in/?s="&SUBSTITUTE($D4," ","+")&"&post_type=product","Robu search") -> Robu search | T4: 85.5 | U4: https://www.alibaba.com/showroom/zynq-7020-development-board.html | W4: =HYPERLINK("https://www.lcsc.com/search?q="&SUBSTITUTE($D4," ","+"),"LCSC search") -> LCSC search | Y4: =HYPERLINK("https://www.mouser.in/c/?q="&SUBSTITUTE($D4," ","+"),"Mouser search") -> Mouser search | AA4: =HYPERLINK("https://www.digikey.in/en/products/filter?keywords="&SUBSTITUTE($D4," ","+"),"DigiKey search") -> DigiKey search | AC4: =Inputs_Assumptions!$B$7 -> 150 | AD4: =Inputs_Assumptions!$B$7 -> 150 | AE4: =Inputs_Assumptions!$B$5 -> 0.1 | AF4: =Inputs_Assumptions!$B$6 -> 0.18 | AG4: =Inputs_Assumptions!$B$4 -> 83 | AJ4: =IF(AH4<>"",(AH4*AG4+AD4)*(1+AE4)*(1+AF4),(M4+AD4)*(1+AF4)) -> 14927 | AK4: =Inputs_Assumptions!$B$9 -> 0.35 | AL4: =IF(AJ4<>"",AJ4/(1-AK4),"") -> 22964.615 | AM4: =Inputs_Assumptions!$B$8 -> 0.18 | AN4: =IF(AND(P4<>"",AJ4<>"",AM4<>""),(P4-AJ4-P4*AM4)/P4,"") -> 0.5258725 | AO4: A | AP4: 2 | AQ4: 4 | AR4: 8 | AS4: 1 | AW4: 2025-12-20 | AX4: 2025-12-21 | BH4: 2025-12-21 | BV4: Risky at planned sell (needs bundle or cheaper sourcing). Gross≈10%. Est Amazon net≈-8% after ~18% fees. | BW4: Direct (B2B) + IndiaMART RFQs; avoid Amazon unless bundled/priced higher; also local resellers. | BX4: Bundle: correct power adapter + USB cable + JTAG cable option + PMOD starter pack + demo bitstream + quick‑start + onboarding call. | BY4: Title: Zynq-7000 Dev Board | Verified/QA Tested | Quick‑Start + Support | GST Invoice Bullets: - Key specs: Dual ARM A9 + FPGA fabric, DDR3 - Use case: Embedded + HW accel - Pre‑tested unit with packaging QC sticker + photo proof before dispatch. - Support: setup guide (QR) + WhatsApp troubleshooting; replacement DOA policy. - Ideal for startups/labs/training centers; bulk pricing available. | BZ4: fpga development board, zynq board, artix board, cyclone board, vivado board, quartus board, fpga starter kit, pmod | CA4: Day1–2 sample+QC | Day3 assets+pack insert QR | Day4 IndiaMART+WhatsApp catalog | Week1 Amazon (kit) | Week1–2 LinkedIn/B2B outreach | Week2 small ads + optimize | Bi‑weekly price recheck | CB4: Pending (missing seller profile) | CC4: Reseller (needs confirmation) | CE4: Unknown | CH4: N | CI4: N | CJ4: 7 | CK4: 7 days DOA replacement; unopened returns as per channel policy. | CL4: Domestic shipment (GST invoice preferred) | CM4: 3 months (board functional; no over-voltage/ESD damage). | CN4: 7–14 days (confirm with supplier) | CO4: N | CR4: 2026-01-06 | CS4: Risky at planned sell (needs bundle or cheaper sourcing). Gross≈10%. Est Amazon net≈-8% after ~18% fees. | Channels: Direct (B2B) + IndiaMART RFQs; avoid Amazon unless bundled/priced higher; also local resellers. | Bundle: Bundle: correct power adapter + USB cable + JTAG cable option + PMOD starter pack + demo bitstream + quick‑start + onboarding call. | CT4: High | CU4: 28.2 | CV4: Demand 2.0/40 (units=1.0); Margin 0.0/30 (GM%=-2867187928.5); Channel 0.0/10 (AmazonNet%=NA); Sourcing 6.2/10 (mode=Both); Lead 10.0/10 (days=7.0); Fit 10.0/10; Penalty 0.0/10.
A5: FPGA-SPARTAN6 | B5: FPGA Board | C5: Board | D5: Spartan-6 Dev Board | E5: AMD/Xilinx | F5: XC6SLX9/16 | G5: Spartan-6 board | H5: Low cost FPGA, basic IO | I5: Education, legacy designs | J5: Students, Colleges | K5: Local | L5: Local | M5: 4200 | N5: 5800 | O5: =IF(AND(M5<>"",N5<>""),(N5-M5)/N5,"") -> 0.27586207 | P5: 4097 | Q5: https://www.amazon.in/Numato-Lab-Spartan-Development-Board/dp/B00JA2FAVS | S5: =HYPERLINK("https://robu.in/?s="&SUBSTITUTE($D5," ","+")&"&post_type=product","Robu search") -> Robu search | T5: 15.06 | U5: https://www.alibaba.com/showroom/spartan-fpga-development-board.html | W5: =HYPERLINK("https://www.lcsc.com/search?q="&SUBSTITUTE($D5," ","+"),"LCSC search") -> LCSC search | Y5: =HYPERLINK("https://www.mouser.in/c/?q="&SUBSTITUTE($D5," ","+"),"Mouser search") -> Mouser search | AA5: =HYPERLINK("https://www.digikey.in/en/products/filter?keywords="&SUBSTITUTE($D5," ","+"),"DigiKey search") -> DigiKey search | AC5: =Inputs_Assumptions!$B$7 -> 150 | AD5: =Inputs_Assumptions!$B$7 -> 150 | AE5: =Inputs_Assumptions!$B$5 -> 0.1 | AF5: =Inputs_Assumptions!$B$6 -> 0.18 | AG5: =Inputs_Assumptions!$B$4 -> 83 | AJ5: =IF(AH5<>"",(AH5*AG5+AD5)*(1+AE5)*(1+AF5),(M5+AD5)*(1+AF5)) -> 5133 | AK5: =Inputs_Assumptions!$B$9 -> 0.35 | AL5: =IF(AJ5<>"",AJ5/(1-AK5),"") -> 7896.9231 | AM5: =Inputs_Assumptions!$B$8 -> 0.18 | AN5: =IF(AND(P5<>"",AJ5<>"",AM5<>""),(P5-AJ5-P5*AM5)/P5,"") -> -0.43286795 | AO5: A | AW5: 2025-12-20 | AX5: 2025-12-21 | BH5: 2025-12-21 | BV5: Works for Direct/B2B; marketplaces need bundle/price-up. Gross≈19%. Est Amazon net≈1% after ~18% fees. | BW5: Direct (B2B) + IndiaMART; Amazon only if bundled/priced higher. | BX5: Bundle: correct power adapter + USB cable + JTAG cable option + PMOD starter pack + demo bitstream + quick‑start + onboarding call. | BY5: Title: Spartan-6 Dev Board | Verified/QA Tested | Quick‑Start + Support | GST Invoice Bullets: - Key specs: Low cost FPGA, basic IO - Use case: Education, legacy designs - Pre‑tested unit with packaging QC sticker + photo proof before dispatch. - Support: setup guide (QR) + WhatsApp troubleshooting; replacement DOA policy. - Ideal for startups/labs/training centers; bulk pricing available. | BZ5: fpga development board, zynq board, artix board, cyclone board, vivado board, quartus board, fpga starter kit, pmod | CA5: Day1–2 sample+QC | Day3 assets+pack insert QR | Day4 IndiaMART+WhatsApp catalog | Week1 Amazon (kit) | Week1–2 LinkedIn/B2B outreach | Week2 small ads + optimize | Bi‑weekly price recheck | CB5: Pending (missing seller profile) | CC5: Reseller (needs confirmation) | CE5: Unknown | CH5: N | CI5: N | CJ5: 7 | CK5: 7 days DOA replacement; unopened returns as per channel policy. | CL5: Domestic shipment (GST invoice preferred) | CM5: 3 months (board functional; no over-voltage/ESD damage). | CN5: 7–14 days (confirm with supplier) | CO5: N | CR5: 2026-01-06 | CS5: Works for Direct/B2B; marketplaces need bundle/price-up. Gross≈19%. Est Amazon net≈1% after ~18% fees. | Channels: Direct (B2B) + IndiaMART; Amazon only if bundled/priced higher. | Bundle: Bundle: correct power adapter + USB cable + JTAG cable option + PMOD starter pack + demo bitstream + quick‑start + onboarding call. | CT5: High | CU5: 31.2 | CV5: Demand 0.0/40 (units=0.0); Margin 0.0/30 (GM%=-9577847408.9); Channel 5.0/10 (AmazonNet%=NA); Sourcing 6.2/10 (mode=Local); Lead 10.0/10 (days=7.0); Fit 10.0/10; Penalty 0.0/10.
A6: FPGA-ICE40UP5K | B6: FPGA Board | C6: Board | D6: iCE40 UltraPlus Dev Board | E6: Lattice | F6: iCE40UP5K | G6: UP5K board | H6: Low-power FPGA, DSP blocks | I6: Ultra-low power edge, learning | J6: Makers, Startups | K6: Both | L6: Import | M6: 2200 | N6: 3500 | O6: =IF(AND(M6<>"",N6<>""),(N6-M6)/N6,"") -> 0.37142857 | Q6: https://www.amazon.in/s?k=iCE40+UltraPlus+Dev+Board+iCE40UP5K | S6: =HYPERLINK("https://robu.in/?s="&SUBSTITUTE($D6," ","+")&"&post_type=product","Robu search") -> Robu search | U6: https://www.alibaba.com/trade/search?SearchText=iCE40+UltraPlus+Dev+Board+iCE40UP5K | W6: =HYPERLINK("https://www.lcsc.com/search?q="&SUBSTITUTE($D6," ","+"),"LCSC search") -> LCSC search | Y6: =HYPERLINK("https://www.mouser.in/c/?q="&SUBSTITUTE($D6," ","+"),"Mouser search") -> Mouser search | AA6: =HYPERLINK("https://www.digikey.in/en/products/filter?keywords="&SUBSTITUTE($D6," ","+"),"DigiKey search") -> DigiKey search | AC6: =Inputs_Assumptions!$B$7 -> 150 | AD6: =Inputs_Assumptions!$B$7 -> 150 | AE6: =Inputs_Assumptions!$B$5 -> 0.1 | AF6: =Inputs_Assumptions!$B$6 -> 0.18 | AG6: =Inputs_Assumptions!$B$4 -> 83 | AJ6: =IF(AH6<>"",(AH6*AG6+AD6)*(1+AE6)*(1+AF6),(M6+AD6)*(1+AF6)) -> 2773 | AK6: =Inputs_Assumptions!$B$9 -> 0.35 | AL6: =IF(AJ6<>"",AJ6/(1-AK6),"") -> 4266.1538 | AM6: =Inputs_Assumptions!$B$8 -> 0.18 | AN6: =IF(AND(P6<>"",AJ6<>"",AM6<>""),(P6-AJ6-P6*AM6)/P6,"") | AO6: A | AP6: 6 | AQ6: 6 | AR6: 12 | AS6: 2 | AW6: 2025-12-20 | AX6: 2025-12-21 | BH6: 2025-12-21 | BV6: Works (healthy margin). Gross≈30%. Est Amazon net≈12% after ~18% fees. | BW6: Amazon (as verified kit) + Direct (B2B) + IndiaMART; also Website/WhatsApp + LinkedIn outreach. | BX6: Bundle: correct power adapter + USB cable + JTAG cable option + PMOD starter pack + demo bitstream + quick‑start + onboarding call. | BY6: Title: iCE40 UltraPlus Dev Board | Verified/QA Tested | Quick‑Start + Support | GST Invoice Bullets: - Key specs: Low-power FPGA, DSP blocks - Use case: Ultra-low power edge, learning - Pre‑tested unit with packaging QC sticker + photo proof before dispatch. - Support: setup guide (QR) + WhatsApp troubleshooting; replacement DOA policy. - Ideal for startups/labs/training centers; bulk pricing available. | BZ6: fpga development board, zynq board, artix board, cyclone board, vivado board, quartus board, fpga starter kit, pmod | CA6: Day1–2 sample+QC | Day3 assets+pack insert QR | Day4 IndiaMART+WhatsApp catalog | Week1 Amazon (kit) | Week1–2 LinkedIn/B2B outreach | Week2 small ads + optimize | Bi‑weekly price recheck | CB6: Pending (missing seller profile) | CC6: Reseller (needs confirmation) | CE6: Unknown | CH6: N | CI6: N | CJ6: 7 | CK6: 7 days DOA replacement; unopened returns as per channel policy. | CL6: Domestic shipment (GST invoice preferred) | CM6: 3 months (board functional; no over-voltage/ESD damage). | CN6: 7–14 days (confirm with supplier) | CO6: N | CR6: 2026-01-06 | CS6: Works (healthy margin). Gross≈30%. Est Amazon net≈12% after ~18% fees. | Channels: Amazon (as verified kit) + Direct (B2B) + IndiaMART; also Website/WhatsApp + LinkedIn outreach. | Bundle: Bundle: correct power adapter + USB cable + JTAG cable option + PMOD starter pack + demo bitstream + quick‑start + onboarding call. | CT6: High | CU6: 35.2 | CV6: Demand 4.0/40 (units=2.0); Margin 0.0/30 (GM%=-19046176089.0); Channel 5.0/10 (AmazonNet%=NA); Sourcing 6.2/10 (mode=Both); Lead 10.0/10 (days=7.0); Fit 10.0/10; Penalty 0.0/10.
A7: FPGA-ECP5-25F | B7: FPGA Board | C7: Board | D7: ECP5 Dev Board | E7: Lattice | F7: LFE5U-25F | G7: 25F board | H7: ECP5 FPGA, SerDes, DDR3 optional | I7: Edge video, custom accel | J7: Startups, Labs | K7: Import | L7: Import | M7: 5800 | N7: 8000 | O7: =IF(AND(M7<>"",N7<>""),(N7-M7)/N7,"") -> 0.275 | P7: 10156.4 | Q7: https://www.amazon.in/Lattice-ECP5-FPGA-RISC-V-Development/dp/B0BKF9NDGZ | S7: =HYPERLINK("https://robu.in/?s="&SUBSTITUTE($D7," ","+")&"&post_type=product","Robu search") -> Robu search | T7: 21.28 | U7: https://m.alibaba.com/showroom/ecp5-fpga.html | W7: =HYPERLINK("https://www.lcsc.com/search?q="&SUBSTITUTE($D7," ","+"),"LCSC search") -> LCSC search | Y7: =HYPERLINK("https://www.mouser.in/c/?q="&SUBSTITUTE($D7," ","+"),"Mouser search") -> Mouser search | AA7: =HYPERLINK("https://www.digikey.in/en/products/filter?keywords="&SUBSTITUTE($D7," ","+"),"DigiKey search") -> DigiKey search | AC7: =Inputs_Assumptions!$B$7 -> 150 | AD7: =Inputs_Assumptions!$B$7 -> 150 | AE7: =Inputs_Assumptions!$B$5 -> 0.1 | AF7: =Inputs_Assumptions!$B$6 -> 0.18 | AG7: =Inputs_Assumptions!$B$4 -> 83 | AJ7: =IF(AH7<>"",(AH7*AG7+AD7)*(1+AE7)*(1+AF7),(M7+AD7)*(1+AF7)) -> 7021 | AK7: =Inputs_Assumptions!$B$9 -> 0.35 | AL7: =IF(AJ7<>"",AJ7/(1-AK7),"") -> 10801.538 | AM7: =Inputs_Assumptions!$B$8 -> 0.18 | AN7: =IF(AND(P7<>"",AJ7<>"",AM7<>""),(P7-AJ7-P7*AM7)/P7,"") -> 0.12871175 | AO7: A | AP7: 3 | AQ7: 6 | AR7: 12 | AS7: 2 | AW7: 2025-12-20 | AX7: 2025-12-21 | BH7: 2025-12-21 | BV7: Works for Direct/B2B; marketplaces need bundle/price-up. Gross≈19%. Est Amazon net≈1% after ~18% fees. | BW7: Direct (B2B) + IndiaMART; Amazon only if bundled/priced higher. | BX7: Bundle: correct power adapter + USB cable + JTAG cable option + PMOD starter pack + demo bitstream + quick‑start + onboarding call. | BY7: Title: ECP5 Dev Board | Verified/QA Tested | Quick‑Start + Support | GST Invoice Bullets: - Key specs: ECP5 FPGA, SerDes, DDR3 optional - Use case: Edge video, custom accel - Pre‑tested unit with packaging QC sticker + photo proof before dispatch. - Support: setup guide (QR) + WhatsApp troubleshooting; replacement DOA policy. - Ideal for startups/labs/training centers; bulk pricing available. | BZ7: fpga development board, zynq board, artix board, cyclone board, vivado board, quartus board, fpga starter kit, pmod | CA7: Day1–2 sample+QC | Day3 assets+pack insert QR | Day4 IndiaMART+WhatsApp catalog | Week1 Amazon (kit) | Week1–2 LinkedIn/B2B outreach | Week2 small ads + optimize | Bi‑weekly price recheck | CB7: Pending (missing seller profile) | CC7: Reseller (needs confirmation) | CE7: Unknown | CH7: N | CI7: N | CJ7: 7 | CK7: 7 days DOA replacement; unopened returns as per channel policy. | CL7: Domestic shipment (GST invoice preferred) | CM7: 3 months (board functional; no over-voltage/ESD damage). | CN7: 7–14 days (confirm with supplier) | CO7: N | CR7: 2026-01-06 | CS7: Works for Direct/B2B; marketplaces need bundle/price-up. Gross≈19%. Est Amazon net≈1% after ~18% fees. | Channels: Direct (B2B) + IndiaMART; Amazon only if bundled/priced higher. | Bundle: Bundle: correct power adapter + USB cable + JTAG cable option + PMOD starter pack + demo bitstream + quick‑start + onboarding call. | CT7: High | CU7: 29 | CV7: Demand 4.0/40 (units=2.0); Margin 0.0/30 (GM%=-9721464621.5); Channel 5.0/10 (AmazonNet%=NA); Sourcing 0.0/10 (mode=Import); Lead 10.0/10 (days=7.0); Fit 10.0/10; Penalty 0.0/10.
A8: FPGA-ECP5-45F | B8: FPGA Board | C8: Board | D8: ECP5 Dev Board | E8: Lattice | F8: LFE5U-45F | G8: 45F board | H8: Mid-range ECP5, better fabric | I8: Edge compute, camera pipelines | J8: Startups, Labs | K8: Import | L8: Import | M8: 7500 | N8: 10200 | O8: =IF(AND(M8<>"",N8<>""),(N8-M8)/N8,"") -> 0.26470588 | Q8: https://www.amazon.in/s?k=ECP5+Dev+Board+LFE5U-45F | S8: =HYPERLINK("https://robu.in/?s="&SUBSTITUTE($D8," ","+")&"&post_type=product","Robu search") -> Robu search | U8: https://www.alibaba.com/trade/search?SearchText=ECP5+Dev+Board+LFE5U-45F | W8: =HYPERLINK("https://www.lcsc.com/search?q="&SUBSTITUTE($D8," ","+"),"LCSC search") -> LCSC search | Y8: =HYPERLINK("https://www.mouser.in/c/?q="&SUBSTITUTE($D8," ","+"),"Mouser search") -> Mouser search | AA8: =HYPERLINK("https://www.digikey.in/en/products/filter?keywords="&SUBSTITUTE($D8," ","+"),"DigiKey search") -> DigiKey search | AC8: =Inputs_Assumptions!$B$7 -> 150 | AD8: =Inputs_Assumptions!$B$7 -> 150 | AE8: =Inputs_Assumptions!$B$5 -> 0.1 | AF8: =Inputs_Assumptions!$B$6 -> 0.18 | AG8: =Inputs_Assumptions!$B$4 -> 83 | AJ8: =IF(AH8<>"",(AH8*AG8+AD8)*(1+AE8)*(1+AF8),(M8+AD8)*(1+AF8)) -> 9027 | AK8: =Inputs_Assumptions!$B$9 -> 0.35 | AL8: =IF(AJ8<>"",AJ8/(1-AK8),"") -> 13887.692 | AM8: =Inputs_Assumptions!$B$8 -> 0.18 | AN8: =IF(AND(P8<>"",AJ8<>"",AM8<>""),(P8-AJ8-P8*AM8)/P8,"") | AO8: B | AR8: 6 | AW8: 2025-12-20 | AX8: 2025-12-21 | BH8: 2025-12-21 | BV8: Works for Direct/B2B; marketplaces need bundle/price-up. Gross≈18%. Est Amazon net≈0% after ~18% fees. | BW8: Direct (B2B) + IndiaMART; Amazon only if bundled/priced higher. | BX8: Bundle: correct power adapter + USB cable + JTAG cable option + PMOD starter pack + demo bitstream + quick‑start + onboarding call. | BY8: Title: ECP5 Dev Board | Verified/QA Tested | Quick‑Start + Support | GST Invoice Bullets: - Key specs: Mid-range ECP5, better fabric - Use case: Edge compute, camera pipelines - Pre‑tested unit with packaging QC sticker + photo proof before dispatch. - Support: setup guide (QR) + WhatsApp troubleshooting; replacement DOA policy. - Ideal for startups/labs/training centers; bulk pricing available. | BZ8: fpga development board, zynq board, artix board, cyclone board, vivado board, quartus board, fpga starter kit, pmod | CA8: Day1–2 sample+QC | Day3 assets+pack insert QR | Day4 IndiaMART+WhatsApp catalog | Week1 Amazon (kit) | Week1–2 LinkedIn/B2B outreach | Week2 small ads + optimize | Bi‑weekly price recheck | CB8: Pending (missing seller profile) | CC8: Reseller (needs confirmation) | CE8: Unknown | CH8: N | CI8: N | CJ8: 7 | CK8: 7 days DOA replacement; unopened returns as per channel policy. | CL8: Domestic shipment (GST invoice preferred) | CM8: 3 months (board functional; no over-voltage/ESD damage). | CN8: 7–14 days (confirm with supplier) | CO8: N | CR8: 2026-01-06 | CS8: Works for Direct/B2B; marketplaces need bundle/price-up. Gross≈18%. Est Amazon net≈0% after ~18% fees. | Channels: Direct (B2B) + IndiaMART; Amazon only if bundled/priced higher. | Bundle: Bundle: correct power adapter + USB cable + JTAG cable option + PMOD starter pack + demo bitstream + quick‑start + onboarding call. | CT8: Medium | CU8: 25 | CV8: Demand 0.0/40 (units=0.0); Margin 0.0/30 (GM%=-8713903711.9); Channel 5.0/10 (AmazonNet%=NA); Sourcing 0.0/10 (mode=Import); Lead 10.0/10 (days=7.0); Fit 10.0/10; Penalty 0.0/10.
A9: FPGA-ECP5-85F | B9: FPGA Board | C9: Board | D9: ECP5 Dev Board | E9: Lattice | F9: LFE5U-85F | G9: 85F board | H9: High-density ECP5 | I9: Advanced edge accel | J9: Startups | K9: Import | L9: Import | M9: 9800 | N9: 13500 | O9: =IF(AND(M9<>"",N9<>""),(N9-M9)/N9,"") -> 0.27407407 | Q9: https://www.amazon.in/s?k=ECP5+Dev+Board+LFE5U-85F | S9: =HYPERLINK("https://robu.in/?s="&SUBSTITUTE($D9," ","+")&"&post_type=product","Robu search") -> Robu search | U9: https://www.alibaba.com/trade/search?SearchText=ECP5+Dev+Board+LFE5U-85F | W9: =HYPERLINK("https://www.lcsc.com/search?q="&SUBSTITUTE($D9," ","+"),"LCSC search") -> LCSC search | Y9: =HYPERLINK("https://www.mouser.in/c/?q="&SUBSTITUTE($D9," ","+"),"Mouser search") -> Mouser search | AA9: =HYPERLINK("https://www.digikey.in/en/products/filter?keywords="&SUBSTITUTE($D9," ","+"),"DigiKey search") -> DigiKey search | AC9: =Inputs_Assumptions!$B$7 -> 150 | AD9: =Inputs_Assumptions!$B$7 -> 150 | AE9: =Inputs_Assumptions!$B$5 -> 0.1 | AF9: =Inputs_Assumptions!$B$6 -> 0.18 | AG9: =Inputs_Assumptions!$B$4 -> 83 | AJ9: =IF(AH9<>"",(AH9*AG9+AD9)*(1+AE9)*(1+AF9),(M9+AD9)*(1+AF9)) -> 11741 | AK9: =Inputs_Assumptions!$B$9 -> 0.35 | AL9: =IF(AJ9<>"",AJ9/(1-AK9),"") -> 18063.077 | AM9: =Inputs_Assumptions!$B$8 -> 0.18 | AN9: =IF(AND(P9<>"",AJ9<>"",AM9<>""),(P9-AJ9-P9*AM9)/P9,"") | AO9: B | AW9: 2025-12-20 | AX9: 2025-12-21 | BH9: 2025-12-21 | BV9: Works for Direct/B2B; marketplaces need bundle/price-up. Gross≈19%. Est Amazon net≈1% after ~18% fees. | BW9: Direct (B2B) + IndiaMART; Amazon only if bundled/priced higher. | BX9: Bundle: correct power adapter + USB cable + JTAG cable option + PMOD starter pack + demo bitstream + quick‑start + onboarding call. | BY9: Title: ECP5 Dev Board | Verified/QA Tested | Quick‑Start + Support | GST Invoice Bullets: - Key specs: High-density ECP5 - Use case: Advanced edge accel - Pre‑tested unit with packaging QC sticker + photo proof before dispatch. - Support: setup guide (QR) + WhatsApp troubleshooting; replacement DOA policy. - Ideal for startups/labs/training centers; bulk pricing available. | BZ9: fpga development board, zynq board, artix board, cyclone board, vivado board, quartus board, fpga starter kit, pmod | CA9: Day1–2 sample+QC | Day3 assets+pack insert QR | Day4 IndiaMART+WhatsApp catalog | Week1 Amazon (kit) | Week1–2 LinkedIn/B2B outreach | Week2 small ads + optimize | Bi‑weekly price recheck | CB9: Pending (missing seller profile) | CC9: Reseller (needs confirmation) | CE9: Unknown | CH9: N | CI9: N | CJ9: 7 | CK9: 7 days DOA replacement; unopened returns as per channel policy. | CL9: Domestic shipment (GST invoice preferred) | CM9: 3 months (board functional; no over-voltage/ESD damage). | CN9: 7–14 days (confirm with supplier) | CO9: N | CR9: 2026-01-06 | CS9: Works for Direct/B2B; marketplaces need bundle/price-up. Gross≈19%. Est Amazon net≈1% after ~18% fees. | Channels: Direct (B2B) + IndiaMART; Amazon only if bundled/priced higher. | Bundle: Bundle: correct power adapter + USB cable + JTAG cable option + PMOD starter pack + demo bitstream + quick‑start + onboarding call. | CT9: Medium | CU9: 25 | CV9: Demand 0.0/40 (units=0.0); Margin 0.0/30 (GM%=-7406808788.3); Channel 5.0/10 (AmazonNet%=NA); Sourcing 0.0/10 (mode=Import); Lead 10.0/10 (days=7.0); Fit 10.0/10; Penalty 0.0/10.
A10: FPGA-MAX10 | B10: FPGA Board | C10: Board | D10: MAX10 Dev Board | E10: Intel/Altera | F10: MAX10 | G10: MAX10 kit | H10: Low-power FPGA + ADC | I10: Industrial control | J10: Colleges, Industry | K10: Both | L10: Import | M10: 6500 | N10: 8800 | O10: =IF(AND(M10<>"",N10<>""),(N10-M10)/N10,"") -> 0.26136364 | P10: 16098 | Q10: https://www.amazon.in/Altera-MAX10-FPGA-Development-Board/dp/B07B4WPKGS | S10: =HYPERLINK("https://robu.in/?s="&SUBSTITUTE($D10," ","+")&"&post_type=product","Robu search") -> Robu search | T10: 81.5 | U10: https://www.alibaba.com/product-detail/DK-DEV-10M50F484-B-MAX-10_1601294733718.html | W10: =HYPERLINK("https://www.lcsc.com/search?q="&SUBSTITUTE($D10," ","+"),"LCSC search") -> LCSC search | Y10: =HYPERLINK("https://www.mouser.in/c/?q="&SUBSTITUTE($D10," ","+"),"Mouser search") -> Mouser search | AA10: =HYPERLINK("https://www.digikey.in/en/products/filter?keywords="&SUBSTITUTE($D10," ","+"),"DigiKey search") -> DigiKey search | AC10: =Inputs_Assumptions!$B$7 -> 150 | AD10: =Inputs_Assumptions!$B$7 -> 150 | AE10: =Inputs_Assumptions!$B$5 -> 0.1 | AF10: =Inputs_Assumptions!$B$6 -> 0.18 | AG10: =Inputs_Assumptions!$B$4 -> 83 | AJ10: =IF(AH10<>"",(AH10*AG10+AD10)*(1+AE10)*(1+AF10),(M10+AD10)*(1+AF10)) -> 7847 | AK10: =Inputs_Assumptions!$B$9 -> 0.35 | AL10: =IF(AJ10<>"",AJ10/(1-AK10),"") -> 12072.308 | AM10: =Inputs_Assumptions!$B$8 -> 0.18 | AN10: =IF(AND(P10<>"",AJ10<>"",AM10<>""),(P10-AJ10-P10*AM10)/P10,"") -> 0.33254814 | AO10: A | AW10: 2025-12-20 | AX10: 2025-12-21 | BH10: 2025-12-21 | BV10: Works for Direct/B2B; marketplaces need bundle/price-up. Gross≈18%. Est Amazon net≈-0% after ~18% fees. | BW10: Direct (B2B) + IndiaMART; Amazon only if bundled/priced higher. | BX10: Bundle: correct power adapter + USB cable + JTAG cable option + PMOD starter pack + demo bitstream + quick‑start + onboarding call. | BY10: Title: MAX10 Dev Board | Verified/QA Tested | Quick‑Start + Support | GST Invoice Bullets: - Key specs: Low-power FPGA + ADC - Use case: Industrial control - Pre‑tested unit with packaging QC sticker + photo proof before dispatch. - Support: setup guide (QR) + WhatsApp troubleshooting; replacement DOA policy. - Ideal for startups/labs/training centers; bulk pricing available. | BZ10: fpga development board, zynq board, artix board, cyclone board, vivado board, quartus board, fpga starter kit, pmod | CA10: Day1–2 sample+QC | Day3 assets+pack insert QR | Day4 IndiaMART+WhatsApp catalog | Week1 Amazon (kit) | Week1–2 LinkedIn/B2B outreach | Week2 small ads + optimize | Bi‑weekly price recheck | CB10: Pending (missing seller profile) | CC10: Reseller (needs confirmation) | CE10: Unknown | CH10: N | CI10: N | CJ10: 7 | CK10: 7 days DOA replacement; unopened returns as per channel policy. | CL10: Domestic shipment (GST invoice preferred) | CM10: 3 months (board functional; no over-voltage/ESD damage). | CN10: 7–14 days (confirm with supplier) | CO10: N | CR10: 2026-01-06 | CS10: Works for Direct/B2B; marketplaces need bundle/price-up. Gross≈18%. Est Amazon net≈-0% after ~18% fees. | Channels: Direct (B2B) + IndiaMART; Amazon only if bundled/priced higher. | Bundle: Bundle: correct power adapter + USB cable + JTAG cable option + PMOD starter pack + demo bitstream + quick‑start + onboarding call. | CT10: High | CU10: 31.2 | CV10: Demand 0.0/40 (units=0.0); Margin 0.0/30 (GM%=-1147842057967056768.0); Channel 5.0/10 (AmazonNet%=NA); Sourcing 6.2/10 (mode=Both); Lead 10.0/10 (days=7.0); Fit 10.0/10; Penalty 0.0/10.
A11: FPGA-CYC5GX | B11: FPGA Board | C11: Board | D11: Cyclone V GX Dev Board | E11: Intel/Altera | F11: Cyclone V GX | G11: GX board | H11: Transceivers, DDR3/DDR4 | I11: High-speed IO prototypes | J11: Industry, Labs | K11: Import | L11: Import | M11: 16500 | N11: 21000 | O11: =IF(AND(M11<>"",N11<>""),(N11-M11)/N11,"") -> 0.21428571 | Q11: https://www.amazon.in/s?k=Cyclone+V+GX+Dev+Board+Cyclone+V+GX | S11: =HYPERLINK("https://robu.in/?s="&SUBSTITUTE($D11," ","+")&"&post_type=product","Robu search") -> Robu search | U11: https://www.alibaba.com/trade/search?SearchText=Cyclone+V+GX+Dev+Board+Cyclone+V+GX | W11: =HYPERLINK("https://www.lcsc.com/search?q="&SUBSTITUTE($D11," ","+"),"LCSC search") -> LCSC search | Y11: =HYPERLINK("https://www.mouser.in/c/?q="&SUBSTITUTE($D11," ","+"),"Mouser search") -> Mouser search | AA11: =HYPERLINK("https://www.digikey.in/en/products/filter?keywords="&SUBSTITUTE($D11," ","+"),"DigiKey search") -> DigiKey search | AC11: =Inputs_Assumptions!$B$7 -> 150 | AD11: =Inputs_Assumptions!$B$7 -> 150 | AE11: =Inputs_Assumptions!$B$5 -> 0.1 | AF11: =Inputs_Assumptions!$B$6 -> 0.18 | AG11: =Inputs_Assumptions!$B$4 -> 83 | AJ11: =IF(AH11<>"",(AH11*AG11+AD11)*(1+AE11)*(1+AF11),(M11+AD11)*(1+AF11)) -> 19647 | AK11: =Inputs_Assumptions!$B$9 -> 0.35 | AL11: =IF(AJ11<>"",AJ11/(1-AK11),"") -> 30226.154 | AM11: =Inputs_Assumptions!$B$8 -> 0.18 | AN11: =IF(AND(P11<>"",AJ11<>"",AM11<>""),(P11-AJ11-P11*AM11)/P11,"") | AO11: C | AW11: 2025-12-20 | AX11: 2025-12-21 | BH11: 2025-12-21 | BV11: Risky at planned sell (needs bundle or cheaper sourcing). Gross≈13%. Est Amazon net≈-5% after ~18% fees. | BW11: Direct (B2B) + IndiaMART RFQs; avoid Amazon unless bundled/priced higher; also local resellers. | BX11: Bundle: correct power adapter + USB cable + JTAG cable option + PMOD starter pack + demo bitstream + quick‑start + onboarding call. | BY11: Title: Cyclone V GX Dev Board | Verified/QA Tested | Quick‑Start + Support | GST Invoice Bullets: - Key specs: Transceivers, DDR3/DDR4 - Use case: High-speed IO prototypes - Pre‑tested unit with packaging QC sticker + photo proof before dispatch. - Support: setup guide (QR) + WhatsApp troubleshooting; replacement DOA policy. - Ideal for startups/labs/training centers; bulk pricing available. | BZ11: fpga development board, zynq board, artix board, cyclone board, vivado board, quartus board, fpga starter kit, pmod | CA11: Day1–2 sample+QC | Day3 assets+pack insert QR | Day4 IndiaMART+WhatsApp catalog | Week1 Amazon (kit) | Week1–2 LinkedIn/B2B outreach | Week2 small ads + optimize | Bi‑weekly price recheck | CB11: Pending (missing seller profile) | CC11: Reseller (needs confirmation) | CE11: Unknown | CH11: N | CI11: N | CJ11: 7 | CK11: 7 days DOA replacement; unopened returns as per channel policy. | CL11: Domestic shipment (GST invoice preferred) | CM11: 3 months (board functional; no over-voltage/ESD damage). | CN11: 7–14 days (confirm with supplier) | CO11: N | CR11: 2026-01-06 | CS11: Risky at planned sell (needs bundle or cheaper sourcing). Gross≈13%. Est Amazon net≈-5% after ~18% fees. | Channels: Direct (B2B) + IndiaMART RFQs; avoid Amazon unless bundled/priced higher; also local resellers. | Bundle: Bundle: correct power adapter + USB cable + JTAG cable option + PMOD starter pack + demo bitstream + quick‑start + onboarding call. | CT11: Low | CU11: 20 | CV11: Demand 0.0/40 (units=0.0); Margin 0.0/30 (GM%=-529100529100529024.0); Channel 0.0/10 (AmazonNet%=NA); Sourcing 0.0/10 (mode=Import); Lead 10.0/10 (days=7.0); Fit 10.0/10; Penalty 0.0/10.
A12: FPGA-CYC10LP | B12: FPGA Board | C12: Board | D12: Cyclone 10 LP Dev Board | E12: Intel/Altera | F12: Cyclone 10 LP | G12: LP kit | H12: Low-power FPGA | I12: Education, control | J12: Colleges | K12: Import | L12: Import | M12: 7200 | N12: 9800 | O12: =IF(AND(M12<>"",N12<>""),(N12-M12)/N12,"") -> 0.26530612 | Q12: https://www.amazon.in/s?k=Cyclone+10+LP+Dev+Board+Cyclone+10+LP | S12: =HYPERLINK("https://robu.in/?s="&SUBSTITUTE($D12," ","+")&"&post_type=product","Robu search") -> Robu search | T12: 99.95 | U12: https://www.alibaba.com/product-detail/Intel-Cyclone-10-LP-FPGA-Development_1601280047239.html | W12: =HYPERLINK("https://www.lcsc.com/search?q="&SUBSTITUTE($D12," ","+"),"LCSC search") -> LCSC search | Y12: =HYPERLINK("https://www.mouser.in/c/?q="&SUBSTITUTE($D12," ","+"),"Mouser search") -> Mouser search | AA12: =HYPERLINK("https://www.digikey.in/en/products/filter?keywords="&SUBSTITUTE($D12," ","+"),"DigiKey search") -> DigiKey search | AC12: =Inputs_Assumptions!$B$7 -> 150 | AD12: =Inputs_Assumptions!$B$7 -> 150 | AE12: =Inputs_Assumptions!$B$5 -> 0.1 | AF12: =Inputs_Assumptions!$B$6 -> 0.18 | AG12: =Inputs_Assumptions!$B$4 -> 83 | AJ12: =IF(AH12<>"",(AH12*AG12+AD12)*(1+AE12)*(1+AF12),(M12+AD12)*(1+AF12)) -> 8673 | AK12: =Inputs_Assumptions!$B$9 -> 0.35 | AL12: =IF(AJ12<>"",AJ12/(1-AK12),"") -> 13343.077 | AM12: =Inputs_Assumptions!$B$8 -> 0.18 | AN12: =IF(AND(P12<>"",AJ12<>"",AM12<>""),(P12-AJ12-P12*AM12)/P12,"") | AO12: B | AR12: 4 | AW12: 2025-12-20 | AX12: 2025-12-21 | BH12: 2025-12-21 | BV12: Works for Direct/B2B; marketplaces need bundle/price-up. Gross≈18%. Est Amazon net≈0% after ~18% fees. | BW12: Direct (B2B) + IndiaMART; Amazon only if bundled/priced higher. | BX12: Bundle: correct power adapter + USB cable + JTAG cable option + PMOD starter pack + demo bitstream + quick‑start + onboarding call. | BY12: Title: Cyclone 10 LP Dev Board | Verified/QA Tested | Quick‑Start + Support | GST Invoice Bullets: - Key specs: Low-power FPGA - Use case: Education, control - Pre‑tested unit with packaging QC sticker + photo proof before dispatch. - Support: setup guide (QR) + WhatsApp troubleshooting; replacement DOA policy. - Ideal for startups/labs/training centers; bulk pricing available. | BZ12: fpga development board, zynq board, artix board, cyclone board, vivado board, quartus board, fpga starter kit, pmod | CA12: Day1–2 sample+QC | Day3 assets+pack insert QR | Day4 IndiaMART+WhatsApp catalog | Week1 Amazon (kit) | Week1–2 LinkedIn/B2B outreach | Week2 small ads + optimize | Bi‑weekly price recheck | CB12: Pending (missing seller profile) | CC12: Reseller (needs confirmation) | CE12: Unknown | CH12: N | CI12: N | CJ12: 7 | CK12: 7 days DOA replacement; unopened returns as per channel policy. | CL12: Domestic shipment (GST invoice preferred) | CM12: 3 months (board functional; no over-voltage/ESD damage). | CN12: 7–14 days (confirm with supplier) | CO12: N | CR12: 2026-01-06 | CS12: Works for Direct/B2B; marketplaces need bundle/price-up. Gross≈18%. Est Amazon net≈0% after ~18% fees. | Channels: Direct (B2B) + IndiaMART; Amazon only if bundled/priced higher. | Bundle: Bundle: correct power adapter + USB cable + JTAG cable option + PMOD starter pack + demo bitstream + quick‑start + onboarding call. | CT12: Medium | CU12: 25 | CV12: Demand 0.0/40 (units=0.0); Margin 0.0/30 (GM%=-1236858378786950912.0); Channel 5.0/10 (AmazonNet%=NA); Sourcing 0.0/10 (mode=Import); Lead 10.0/10 (days=7.0); Fit 10.0/10; Penalty 0.0/10.
A13: FPGA-ZU-DEV | B13: FPGA Board | C13: Board | D13: Zynq UltraScale+ Dev Kit | E13: AMD/Xilinx | F13: ZU3EG/ZU5EV | G13: UltraScale+ kit | H13: ARM A53 + FPGA fabric | I13: High-end edge compute | J13: Industry, funded startups | K13: Import | L13: Import | M13: 65000 | N13: 82000 | O13: =IF(AND(M13<>"",N13<>""),(N13-M13)/N13,"") -> 0.20731707 | Q13: https://www.amazon.in/s?k=Zynq+UltraScale%2B+Dev+Kit+ZU3EG%2FZU5EV | S13: =HYPERLINK("https://robu.in/?s="&SUBSTITUTE($D13," ","+")&"&post_type=product","Robu search") -> Robu search | U13: https://www.alibaba.com/trade/search?SearchText=Zynq+UltraScale%2B+Dev+Kit+ZU3EG%2FZU5EV | W13: =HYPERLINK("https://www.lcsc.com/search?q="&SUBSTITUTE($D13," ","+"),"LCSC search") -> LCSC search | Y13: =HYPERLINK("https://www.mouser.in/c/?q="&SUBSTITUTE($D13," ","+"),"Mouser search") -> Mouser search | AA13: =HYPERLINK("https://www.digikey.in/en/products/filter?keywords="&SUBSTITUTE($D13," ","+"),"DigiKey search") -> DigiKey search | AC13: =Inputs_Assumptions!$B$7 -> 150 | AD13: =Inputs_Assumptions!$B$7 -> 150 | AE13: =Inputs_Assumptions!$B$5 -> 0.1 | AF13: =Inputs_Assumptions!$B$6 -> 0.18 | AG13: =Inputs_Assumptions!$B$4 -> 83 | AJ13: =IF(AH13<>"",(AH13*AG13+AD13)*(1+AE13)*(1+AF13),(M13+AD13)*(1+AF13)) -> 76877 | AK13: =Inputs_Assumptions!$B$9 -> 0.35 | AL13: =IF(AJ13<>"",AJ13/(1-AK13),"") -> 118272.31 | AM13: =Inputs_Assumptions!$B$8 -> 0.18 | AN13: =IF(AND(P13<>"",AJ13<>"",AM13<>""),(P13-AJ13-P13*AM13)/P13,"") | AO13: C | AW13: 2025-12-20 | AX13: 2025-12-21 | BH13: 2025-12-21 | BV13: Risky at planned sell (needs bundle or cheaper sourcing). Gross≈12%. Est Amazon net≈-6% after ~18% fees. | BW13: Direct (B2B) + IndiaMART RFQs; avoid Amazon unless bundled/priced higher; also local resellers. | BX13: Bundle: correct power adapter + USB cable + JTAG cable option + PMOD starter pack + demo bitstream + quick‑start + onboarding call. | BY13: Title: Zynq UltraScale+ Dev Kit | Verified/QA Tested | Quick‑Start + Support | GST Invoice Bullets: - Key specs: ARM A53 + FPGA fabric - Use case: High-end edge compute - Pre‑tested unit with packaging QC sticker + photo proof before dispatch. - Support: setup guide (QR) + WhatsApp troubleshooting; replacement DOA policy. - Ideal for startups/labs/training centers; bulk pricing available. | BZ13: fpga development board, zynq board, artix board, cyclone board, vivado board, quartus board, fpga starter kit, pmod | CA13: Day1–2 sample+QC | Day3 assets+pack insert QR | Day4 IndiaMART+WhatsApp catalog | Week1 Amazon (kit) | Week1–2 LinkedIn/B2B outreach | Week2 small ads + optimize | Bi‑weekly price recheck | CB13: Pending (missing seller profile) | CC13: Reseller (needs confirmation) | CE13: Unknown | CH13: N | CI13: N | CJ13: 7 | CK13: 7 days DOA replacement; unopened returns as per channel policy. | CL13: Domestic shipment (GST invoice preferred) | CM13: 3 months (board functional; no over-voltage/ESD damage). | CN13: 7–14 days (confirm with supplier) | CO13: N | CR13: 2026-01-06 | CS13: Risky at planned sell (needs bundle or cheaper sourcing). Gross≈12%. Est Amazon net≈-6% after ~18% fees. | Channels: Direct (B2B) + IndiaMART RFQs; avoid Amazon unless bundled/priced higher; also local resellers. | Bundle: Bundle: correct power adapter + USB cable + JTAG cable option + PMOD starter pack + demo bitstream + quick‑start + onboarding call. | CT13: Low | CU13: 20 | CV13: Demand 0.0/40 (units=0.0); Margin 0.0/30 (GM%=-160137964794062464.0); Channel 0.0/10 (AmazonNet%=NA); Sourcing 0.0/10 (mode=Import); Lead 10.0/10 (days=7.0); Fit 10.0/10; Penalty 0.0/10.
A14: SOM-ULTRA96V2 | B14: SOM Module | C14: SOM | D14: Ultra96-V2 SOM | E14: Avnet | F14: Ultra96-V2 | G14: Zynq MPSoC | H14: Zynq UltraScale+ MPSoC, WiFi/BT | I14: Embedded AI prototyping | J14: Startups, Labs | K14: Import | L14: Import | M14: 22000 | N14: 28500 | O14: =IF(AND(M14<>"",N14<>""),(N14-M14)/N14,"") -> 0.22807018 | Q14: https://www.amazon.in/s?k=Ultra96-V2+SOM+Ultra96-V2 | S14: =HYPERLINK("https://robu.in/?s="&SUBSTITUTE($D14," ","+")&"&post_type=product","Robu search") -> Robu search | U14: https://www.alibaba.com/trade/search?SearchText=Ultra96-V2+SOM+Ultra96-V2 | W14: =HYPERLINK("https://www.lcsc.com/search?q="&SUBSTITUTE($D14," ","+"),"LCSC search") -> LCSC search | Y14: =HYPERLINK("https://www.mouser.in/c/?q="&SUBSTITUTE($D14," ","+"),"Mouser search") -> Mouser search | AA14: =HYPERLINK("https://www.digikey.in/en/products/filter?keywords="&SUBSTITUTE($D14," ","+"),"DigiKey search") -> DigiKey search | AC14: =Inputs_Assumptions!$B$7 -> 150 | AD14: =Inputs_Assumptions!$B$7 -> 150 | AE14: =Inputs_Assumptions!$B$5 -> 0.1 | AF14: =Inputs_Assumptions!$B$6 -> 0.18 | AG14: =Inputs_Assumptions!$B$4 -> 83 | AJ14: =IF(AH14<>"",(AH14*AG14+AD14)*(1+AE14)*(1+AF14),(M14+AD14)*(1+AF14)) -> 26137 | AK14: =Inputs_Assumptions!$B$9 -> 0.35 | AL14: =IF(AJ14<>"",AJ14/(1-AK14),"") -> 40210.769 | AM14: =Inputs_Assumptions!$B$8 -> 0.18 | AN14: =IF(AND(P14<>"",AJ14<>"",AM14<>""),(P14-AJ14-P14*AM14)/P14,"") | AO14: C | AW14: 2025-12-20 | AX14: 2025-12-21 | BH14: 2025-12-21 | BV14: Risky at planned sell (needs bundle or cheaper sourcing). Gross≈14%. Est Amazon net≈-4% after ~18% fees. | BW14: Direct (B2B) + IndiaMART RFQs; avoid Amazon unless bundled/priced higher; also local resellers. | BX14: Add: essentials kit (cables/adapters) + quick‑start card + basic support + 7‑day DOA replacement. | BY14: Title: Ultra96-V2 SOM | Verified/QA Tested | Quick‑Start + Support | GST Invoice Bullets: - Key specs: Zynq UltraScale+ MPSoC, WiFi/BT - Use case: Embedded AI prototyping - Pre‑tested unit with packaging QC sticker + photo proof before dispatch. - Support: setup guide (QR) + WhatsApp troubleshooting; replacement DOA policy. - Ideal for startups/labs/training centers; bulk pricing available. | BZ14: electronics module, dev kit, maker kit, embedded components | CA14: Day1–2 sample+QC | Day3 assets+pack insert QR | Day4 IndiaMART+WhatsApp catalog | Week1 Amazon (kit) | Week1–2 LinkedIn/B2B outreach | Week2 small ads + optimize | Bi‑weekly price recheck | CB14: Pending (missing seller profile) | CC14: Reseller (needs confirmation) | CE14: Unknown | CH14: N | CI14: N | CJ14: 7 | CK14: Marketplace return policy; 7 days DOA replacement. | CL14: Domestic shipment (GST invoice preferred) | CM14: 30 days replacement for DOA. | CN14: 7–14 days (confirm with supplier) | CO14: N | CR14: 2026-01-06 | CS14: Risky at planned sell (needs bundle or cheaper sourcing). Gross≈14%. Est Amazon net≈-4% after ~18% fees. | Channels: Direct (B2B) + IndiaMART RFQs; avoid Amazon unless bundled/priced higher; also local resellers. | Bundle: Add: essentials kit (cables/adapters) + quick‑start card + basic support + 7‑day DOA replacement. | CT14: Low | CU14: 11 | CV14: Demand 0.0/40 (units=0.0); Margin 0.0/30 (GM%=-496189968916285568.0); Channel 0.0/10 (AmazonNet%=NA); Sourcing 0.0/10 (mode=Import); Lead 10.0/10 (days=7.0); Fit 6.0/10; Penalty 5.0/10.
A15: SOM-KRIA-KV260 | B15: SOM Module | C15: SOM | D15: Kria KV260 Vision AI Starter Kit | E15: AMD/Xilinx | F15: KV260 | G15: Vision AI kit | H15: Kria SOM + carrier, vision ready | I15: Vision AI prototypes | J15: Startups | K15: Import | L15: Import | M15: 28000 | N15: 36000 | O15: =IF(AND(M15<>"",N15<>""),(N15-M15)/N15,"") -> 0.22222222 | Q15: https://www.amazon.in/s?k=Kria+KV260+Vision+AI+Starter+Kit+KV260 | S15: =HYPERLINK("https://robu.in/?s="&SUBSTITUTE($D15," ","+")&"&post_type=product","Robu search") -> Robu search | T15: 338.27 | U15: https://www.alibaba.com/product-detail/Original-Development-Board-Modules-KRIA-KV260_1600861591580.html | W15: =HYPERLINK("https://www.lcsc.com/search?q="&SUBSTITUTE($D15," ","+"),"LCSC search") -> LCSC search | Y15: =HYPERLINK("https://www.mouser.in/c/?q="&SUBSTITUTE($D15," ","+"),"Mouser search") -> Mouser search | AA15: =HYPERLINK("https://www.digikey.in/en/products/filter?keywords="&SUBSTITUTE($D15," ","+"),"DigiKey search") -> DigiKey search | AC15: =Inputs_Assumptions!$B$7 -> 150 | AD15: =Inputs_Assumptions!$B$7 -> 150 | AE15: =Inputs_Assumptions!$B$5 -> 0.1 | AF15: =Inputs_Assumptions!$B$6 -> 0.18 | AG15: =Inputs_Assumptions!$B$4 -> 83 | AJ15: =IF(AH15<>"",(AH15*AG15+AD15)*(1+AE15)*(1+AF15),(M15+AD15)*(1+AF15)) -> 33217 | AK15: =Inputs_Assumptions!$B$9 -> 0.35 | AL15: =IF(AJ15<>"",AJ15/(1-AK15),"") -> 51103.077 | AM15: =Inputs_Assumptions!$B$8 -> 0.18 | AN15: =IF(AND(P15<>"",AJ15<>"",AM15<>""),(P15-AJ15-P15*AM15)/P15,"") | AO15: C | AW15: 2025-12-20 | AX15: 2025-12-21 | BH15: 2025-12-21 | BV15: Risky at planned sell (needs bundle or cheaper sourcing). Gross≈13%. Est Amazon net≈-5% after ~18% fees. | BW15: Direct (B2B) + IndiaMART RFQs; avoid Amazon unless bundled/priced higher; also local resellers. | BX15: Add: essentials kit (cables/adapters) + quick‑start card + basic support + 7‑day DOA replacement. | BY15: Title: Kria KV260 Vision AI Starter Kit | Verified/QA Tested | Quick‑Start + Support | GST Invoice Bullets: - Key specs: Kria SOM + carrier, vision ready - Use case: Vision AI prototypes - Pre‑tested unit with packaging QC sticker + photo proof before dispatch. - Support: setup guide (QR) + WhatsApp troubleshooting; replacement DOA policy. - Ideal for startups/labs/training centers; bulk pricing available. | BZ15: electronics module, dev kit, maker kit, embedded components | CA15: Day1–2 sample+QC | Day3 assets+pack insert QR | Day4 IndiaMART+WhatsApp catalog | Week1 Amazon (kit) | Week1–2 LinkedIn/B2B outreach | Week2 small ads + optimize | Bi‑weekly price recheck | CB15: Pending (missing seller profile) | CC15: Reseller (needs confirmation) | CE15: Unknown | CH15: N | CI15: N | CJ15: 7 | CK15: Marketplace return policy; 7 days DOA replacement. | CL15: Domestic shipment (GST invoice preferred) | CM15: 30 days replacement for DOA. | CN15: 7–14 days (confirm with supplier) | CO15: N | CR15: 2026-01-06 | CS15: Risky at planned sell (needs bundle or cheaper sourcing). Gross≈13%. Est Amazon net≈-5% after ~18% fees. | Channels: Direct (B2B) + IndiaMART RFQs; avoid Amazon unless bundled/priced higher; also local resellers. | Bundle: Add: essentials kit (cables/adapters) + quick‑start card + basic support + 7‑day DOA replacement. | CT15: Low | CU15: 15 | CV15: Demand 0.0/40 (units=0.0); Margin 0.0/30 (GM%=-420875419864309632.0); Channel 0.0/10 (AmazonNet%=NA); Sourcing 0.0/10 (mode=Import); Lead 10.0/10 (days=7.0); Fit 10.0/10; Penalty 5.0/10.
A16: SOM-ZYBO-Z7 | B16: SOM Module | C16: Board | D16: Zybo Z7-20 | E16: Digilent | F16: Zybo Z7-20 | G16: Zynq-7020 | H16: Zynq 7020 board | I16: Embedded FPGA learning | J16: Students, Labs | K16: Import | L16: Import | M16: 19000 | N16: 24500 | O16: =IF(AND(M16<>"",N16<>""),(N16-M16)/N16,"") -> 0.2244898 | P16: 50750.1 | Q16: https://www.amazon.in/Digilent-Zybo-Z7-Zynq-7000-Development/dp/B0797G4485 | S16: =HYPERLINK("https://robu.in/?s="&SUBSTITUTE($D16," ","+")&"&post_type=product","Robu search") -> Robu search | U16: https://www.alibaba.com/trade/search?SearchText=Zybo+Z7-20+Zybo+Z7-20 | W16: =HYPERLINK("https://www.lcsc.com/search?q="&SUBSTITUTE($D16," ","+"),"LCSC search") -> LCSC search | Y16: =HYPERLINK("https://www.mouser.in/c/?q="&SUBSTITUTE($D16," ","+"),"Mouser search") -> Mouser search | AA16: =HYPERLINK("https://www.digikey.in/en/products/filter?keywords="&SUBSTITUTE($D16," ","+"),"DigiKey search") -> DigiKey search | AC16: =Inputs_Assumptions!$B$7 -> 150 | AD16: =Inputs_Assumptions!$B$7 -> 150 | AE16: =Inputs_Assumptions!$B$5 -> 0.1 | AF16: =Inputs_Assumptions!$B$6 -> 0.18 | AG16: =Inputs_Assumptions!$B$4 -> 83 | AJ16: =IF(AH16<>"",(AH16*AG16+AD16)*(1+AE16)*(1+AF16),(M16+AD16)*(1+AF16)) -> 22597 | AK16: =Inputs_Assumptions!$B$9 -> 0.35 | AL16: =IF(AJ16<>"",AJ16/(1-AK16),"") -> 34764.615 | AM16: =Inputs_Assumptions!$B$8 -> 0.18 | AN16: =IF(AND(P16<>"",AJ16<>"",AM16<>""),(P16-AJ16-P16*AM16)/P16,"") -> 0.37473979 | AO16: C | AW16: 2025-12-20 | AX16: 2025-12-21 | BH16: 2025-12-21 | BV16: Risky at planned sell (needs bundle or cheaper sourcing). Gross≈14%. Est Amazon net≈-4% after ~18% fees. | BW16: Direct (B2B) + IndiaMART RFQs; avoid Amazon unless bundled/priced higher; also local resellers. | BX16: Add: essentials kit (cables/adapters) + quick‑start card + basic support + 7‑day DOA replacement. | BY16: Title: Zybo Z7-20 | Verified/QA Tested | Quick‑Start + Support | GST Invoice Bullets: - Key specs: Zynq 7020 board - Use case: Embedded FPGA learning - Pre‑tested unit with packaging QC sticker + photo proof before dispatch. - Support: setup guide (QR) + WhatsApp troubleshooting; replacement DOA policy. - Ideal for startups/labs/training centers; bulk pricing available. | BZ16: electronics module, dev kit, maker kit, embedded components | CA16: Day1–2 sample+QC | Day3 assets+pack insert QR | Day4 IndiaMART+WhatsApp catalog | Week1 Amazon (kit) | Week1–2 LinkedIn/B2B outreach | Week2 small ads + optimize | Bi‑weekly price recheck | CB16: Pending (missing seller profile) | CC16: Reseller (needs confirmation) | CE16: Unknown | CH16: N | CI16: N | CJ16: 7 | CK16: Marketplace return policy; 7 days DOA replacement. | CL16: Domestic shipment (GST invoice preferred) | CM16: 30 days replacement for DOA. | CN16: 7–14 days (confirm with supplier) | CO16: N | CR16: 2026-01-06 | CS16: Risky at planned sell (needs bundle or cheaper sourcing). Gross≈14%. Est Amazon net≈-4% after ~18% fees. | Channels: Direct (B2B) + IndiaMART RFQs; avoid Amazon unless bundled/priced higher; also local resellers. | Bundle: Add: essentials kit (cables/adapters) + quick‑start card + basic support + 7‑day DOA replacement. | CT16: Low | CU16: 11 | CV16: Demand 0.0/40 (units=0.0); Margin 0.0/30 (GM%=-659657800657802240.0); Channel 0.0/10 (AmazonNet%=NA); Sourcing 0.0/10 (mode=Import); Lead 10.0/10 (days=7.0); Fit 6.0/10; Penalty 5.0/10.
A17: SOM-ARTY-A7 | B17: SOM Module | C17: Board | D17: Arty A7-35T | E17: Digilent | F17: Arty A7-35T | G17: Artix-7 | H17: Artix-7 + DDR3 | I17: FPGA education + prototypes | J17: Students, Labs | K17: Import | L17: Import | M17: 17500 | N17: 22500 | O17: =IF(AND(M17<>"",N17<>""),(N17-M17)/N17,"") -> 0.22222222 | P17: 3371 | Q17: https://www.amazon.in/Arty-A7-Artix-7-Development-Hobbyists/dp/B07D1DVRG6 | S17: =HYPERLINK("https://robu.in/?s="&SUBSTITUTE($D17," ","+")&"&post_type=product","Robu search") -> Robu search | T17: 282.8 | U17: https://www.alibaba.com/showroom/xilinx-fpga-kit.html | W17: =HYPERLINK("https://www.lcsc.com/search?q="&SUBSTITUTE($D17," ","+"),"LCSC search") -> LCSC search | Y17: =HYPERLINK("https://www.mouser.in/c/?q="&SUBSTITUTE($D17," ","+"),"Mouser search") -> Mouser search | AA17: =HYPERLINK("https://www.digikey.in/en/products/filter?keywords="&SUBSTITUTE($D17," ","+"),"DigiKey search") -> DigiKey search | AC17: =Inputs_Assumptions!$B$7 -> 150 | AD17: =Inputs_Assumptions!$B$7 -> 150 | AE17: =Inputs_Assumptions!$B$5 -> 0.1 | AF17: =Inputs_Assumptions!$B$6 -> 0.18 | AG17: =Inputs_Assumptions!$B$4 -> 83 | AJ17: =IF(AH17<>"",(AH17*AG17+AD17)*(1+AE17)*(1+AF17),(M17+AD17)*(1+AF17)) -> 20827 | AK17: =Inputs_Assumptions!$B$9 -> 0.35 | AL17: =IF(AJ17<>"",AJ17/(1-AK17),"") -> 32041.538 | AM17: =Inputs_Assumptions!$B$8 -> 0.18 | AN17: =IF(AND(P17<>"",AJ17<>"",AM17<>""),(P17-AJ17-P17*AM17)/P17,"") -> -5.3582854 | AO17: C | AW17: 2025-12-20 | AX17: 2025-12-21 | BH17: 2025-12-21 | BV17: Risky at planned sell (needs bundle or cheaper sourcing). Gross≈13%. Est Amazon net≈-5% after ~18% fees. | BW17: Direct (B2B) + IndiaMART RFQs; avoid Amazon unless bundled/priced higher; also local resellers. | BX17: Add: essentials kit (cables/adapters) + quick‑start card + basic support + 7‑day DOA replacement. | BY17: Title: Arty A7-35T | Verified/QA Tested | Quick‑Start + Support | GST Invoice Bullets: - Key specs: Artix-7 + DDR3 - Use case: FPGA education + prototypes - Pre‑tested unit with packaging QC sticker + photo proof before dispatch. - Support: setup guide (QR) + WhatsApp troubleshooting; replacement DOA policy. - Ideal for startups/labs/training centers; bulk pricing available. | BZ17: electronics module, dev kit, maker kit, embedded components | CA17: Day1–2 sample+QC | Day3 assets+pack insert QR | Day4 IndiaMART+WhatsApp catalog | Week1 Amazon (kit) | Week1–2 LinkedIn/B2B outreach | Week2 small ads + optimize | Bi‑weekly price recheck | CB17: Pending (missing seller profile) | CC17: Reseller (needs confirmation) | CE17: Unknown | CH17: N | CI17: N | CJ17: 7 | CK17: Marketplace return policy; 7 days DOA replacement. | CL17: Domestic shipment (GST invoice preferred) | CM17: 30 days replacement for DOA. | CN17: 7–14 days (confirm with supplier) | CO17: N | CR17: 2026-01-06 | CS17: Risky at planned sell (needs bundle or cheaper sourcing). Gross≈13%. Est Amazon net≈-5% after ~18% fees. | Channels: Direct (B2B) + IndiaMART RFQs; avoid Amazon unless bundled/priced higher; also local resellers. | Bundle: Add: essentials kit (cables/adapters) + quick‑start card + basic support + 7‑day DOA replacement. | CT17: Low | CU17: 11 | CV17: Demand 0.0/40 (units=0.0); Margin 0.0/30 (GM%=-763187427427429760.0); Channel 0.0/10 (AmazonNet%=NA); Sourcing 0.0/10 (mode=Import); Lead 10.0/10 (days=7.0); Fit 6.0/10; Penalty 5.0/10.
